[2022-11-18T06:29:41.743+0000] {taskinstance.py:1165} INFO - Dependencies all met for <TaskInstance: jobs_analysis.Create_Tables scheduled__2022-11-17T00:00:00+00:00 [queued]>
[2022-11-18T06:29:41.748+0000] {taskinstance.py:1165} INFO - Dependencies all met for <TaskInstance: jobs_analysis.Create_Tables scheduled__2022-11-17T00:00:00+00:00 [queued]>
[2022-11-18T06:29:41.749+0000] {taskinstance.py:1362} INFO - 
--------------------------------------------------------------------------------
[2022-11-18T06:29:41.749+0000] {taskinstance.py:1363} INFO - Starting attempt 4 of 4
[2022-11-18T06:29:41.749+0000] {taskinstance.py:1364} INFO - 
--------------------------------------------------------------------------------
[2022-11-18T06:29:41.759+0000] {taskinstance.py:1383} INFO - Executing <Task(PostgresOperator): Create_Tables> on 2022-11-17 00:00:00+00:00
[2022-11-18T06:29:41.761+0000] {standard_task_runner.py:55} INFO - Started process 7661 to run task
[2022-11-18T06:29:41.764+0000] {standard_task_runner.py:82} INFO - Running: ['airflow', 'tasks', 'run', 'jobs_analysis', 'Create_Tables', 'scheduled__2022-11-17T00:00:00+00:00', '--job-id', '16', '--raw', '--subdir', 'DAGS_FOLDER/jobs_dag.py', '--cfg-path', '/tmp/tmp9p8tbybw']
[2022-11-18T06:29:41.765+0000] {standard_task_runner.py:83} INFO - Job 16: Subtask Create_Tables
[2022-11-18T06:29:41.798+0000] {task_command.py:376} INFO - Running <TaskInstance: jobs_analysis.Create_Tables scheduled__2022-11-17T00:00:00+00:00 [running]> on host ip-172-31-2-28.us-west-1.compute.internal
[2022-11-18T06:29:41.831+0000] {taskinstance.py:1590} INFO - Exporting the following env vars:
AIRFLOW_CTX_DAG_EMAIL=lohitha.vanteru@sjsu.edu
AIRFLOW_CTX_DAG_OWNER=Theinsightco
AIRFLOW_CTX_DAG_ID=jobs_analysis
AIRFLOW_CTX_TASK_ID=Create_Tables
AIRFLOW_CTX_EXECUTION_DATE=2022-11-17T00:00:00+00:00
AIRFLOW_CTX_TRY_NUMBER=4
AIRFLOW_CTX_DAG_RUN_ID=scheduled__2022-11-17T00:00:00+00:00
[2022-11-18T06:29:41.837+0000] {taskinstance.py:1851} ERROR - Task failed with exception
Traceback (most recent call last):
  File "/home/ubuntu/.venv/lib/python3.10/site-packages/airflow/providers/postgres/operators/postgres.py", line 94, in execute
    self.hook.run(self.sql, self.autocommit, parameters=self.parameters)
  File "/home/ubuntu/.venv/lib/python3.10/site-packages/airflow/providers/common/sql/hooks/sql.py", line 288, in run
    with closing(self.get_conn()) as conn:
  File "/home/ubuntu/.venv/lib/python3.10/site-packages/airflow/providers/postgres/hooks/postgres.py", line 88, in get_conn
    conn = deepcopy(self.connection or self.get_connection(conn_id))
  File "/home/ubuntu/.venv/lib/python3.10/site-packages/airflow/hooks/base.py", line 70, in get_connection
    conn = Connection.get_connection_from_secrets(conn_id)
  File "/home/ubuntu/.venv/lib/python3.10/site-packages/airflow/models/connection.py", line 432, in get_connection_from_secrets
    raise AirflowNotFoundException(f"The conn_id `{conn_id}` isn't defined")
airflow.exceptions.AirflowNotFoundException: The conn_id `redshift_tci` isn't defined
[2022-11-18T06:29:41.839+0000] {taskinstance.py:1401} INFO - Marking task as FAILED. dag_id=jobs_analysis, task_id=Create_Tables, execution_date=20221117T000000, start_date=20221118T062941, end_date=20221118T062941
[2022-11-18T06:29:41.847+0000] {logging_mixin.py:120} WARNING - /home/ubuntu/.venv/lib/python3.10/site-packages/airflow/utils/email.py:120 RemovedInAirflow3Warning: Fetching SMTP credentials from configuration variables will be deprecated in a future release. Please set credentials using a connection instead.
[2022-11-18T06:29:41.847+0000] {configuration.py:569} WARNING - section/key [smtp/smtp_user] not found in config
[2022-11-18T06:29:41.847+0000] {email.py:229} INFO - Email alerting: attempt 1
[2022-11-18T06:29:41.849+0000] {configuration.py:569} WARNING - section/key [smtp/smtp_user] not found in config
[2022-11-18T06:29:41.849+0000] {email.py:229} INFO - Email alerting: attempt 1
[2022-11-18T06:29:41.850+0000] {taskinstance.py:1914} ERROR - Failed to send email to: lohitha.vanteru@sjsu.edu
Traceback (most recent call last):
  File "/home/ubuntu/.venv/lib/python3.10/site-packages/airflow/models/taskinstance.py", line 1457, in _run_raw_task
    self._execute_task_with_callbacks(context, test_mode)
  File "/home/ubuntu/.venv/lib/python3.10/site-packages/airflow/models/taskinstance.py", line 1603, in _execute_task_with_callbacks
    result = self._execute_task(context, task_orig)
  File "/home/ubuntu/.venv/lib/python3.10/site-packages/airflow/models/taskinstance.py", line 1664, in _execute_task
    result = execute_callable(context=context)
  File "/home/ubuntu/.venv/lib/python3.10/site-packages/airflow/providers/postgres/operators/postgres.py", line 94, in execute
    self.hook.run(self.sql, self.autocommit, parameters=self.parameters)
  File "/home/ubuntu/.venv/lib/python3.10/site-packages/airflow/providers/common/sql/hooks/sql.py", line 288, in run
    with closing(self.get_conn()) as conn:
  File "/home/ubuntu/.venv/lib/python3.10/site-packages/airflow/providers/postgres/hooks/postgres.py", line 88, in get_conn
    conn = deepcopy(self.connection or self.get_connection(conn_id))
  File "/home/ubuntu/.venv/lib/python3.10/site-packages/airflow/hooks/base.py", line 70, in get_connection
    conn = Connection.get_connection_from_secrets(conn_id)
  File "/home/ubuntu/.venv/lib/python3.10/site-packages/airflow/models/connection.py", line 432, in get_connection_from_secrets
    raise AirflowNotFoundException(f"The conn_id `{conn_id}` isn't defined")
airflow.exceptions.AirflowNotFoundException: The conn_id `redshift_tci` isn't defined

During handling of the above exception, another exception occurred:

Traceback (most recent call last):
  File "/home/ubuntu/.venv/lib/python3.10/site-packages/airflow/models/taskinstance.py", line 2315, in email_alert
    send_email(task.email, subject, html_content)
  File "/home/ubuntu/.venv/lib/python3.10/site-packages/airflow/utils/email.py", line 59, in send_email
    return backend(
  File "/home/ubuntu/.venv/lib/python3.10/site-packages/airflow/utils/email.py", line 120, in send_email_smtp
    send_mime_email(e_from=mail_from, e_to=recipients, mime_msg=msg, conn_id=conn_id, dryrun=dryrun)
  File "/home/ubuntu/.venv/lib/python3.10/site-packages/airflow/utils/email.py", line 231, in send_mime_email
    smtp_conn = _get_smtp_connection(smtp_host, smtp_port, smtp_timeout, smtp_ssl)
  File "/home/ubuntu/.venv/lib/python3.10/site-packages/airflow/utils/email.py", line 265, in _get_smtp_connection
    else smtplib.SMTP(host=host, port=port, timeout=timeout)
  File "/usr/lib/python3.10/smtplib.py", line 255, in __init__
    (code, msg) = self.connect(host, port)
  File "/usr/lib/python3.10/smtplib.py", line 341, in connect
    self.sock = self._get_socket(host, port, self.timeout)
  File "/usr/lib/python3.10/smtplib.py", line 312, in _get_socket
    return socket.create_connection((host, port), timeout,
  File "/usr/lib/python3.10/socket.py", line 845, in create_connection
    raise err
  File "/usr/lib/python3.10/socket.py", line 833, in create_connection
    sock.connect(sa)
ConnectionRefusedError: [Errno 111] Connection refused

During handling of the above exception, another exception occurred:

Traceback (most recent call last):
  File "/home/ubuntu/.venv/lib/python3.10/site-packages/airflow/models/taskinstance.py", line 1912, in handle_failure
    self.email_alert(error, task)
  File "/home/ubuntu/.venv/lib/python3.10/site-packages/airflow/models/taskinstance.py", line 2317, in email_alert
    send_email(task.email, subject, html_content_err)
  File "/home/ubuntu/.venv/lib/python3.10/site-packages/airflow/utils/email.py", line 59, in send_email
    return backend(
  File "/home/ubuntu/.venv/lib/python3.10/site-packages/airflow/utils/email.py", line 120, in send_email_smtp
    send_mime_email(e_from=mail_from, e_to=recipients, mime_msg=msg, conn_id=conn_id, dryrun=dryrun)
  File "/home/ubuntu/.venv/lib/python3.10/site-packages/airflow/utils/email.py", line 231, in send_mime_email
    smtp_conn = _get_smtp_connection(smtp_host, smtp_port, smtp_timeout, smtp_ssl)
  File "/home/ubuntu/.venv/lib/python3.10/site-packages/airflow/utils/email.py", line 265, in _get_smtp_connection
    else smtplib.SMTP(host=host, port=port, timeout=timeout)
  File "/usr/lib/python3.10/smtplib.py", line 255, in __init__
    (code, msg) = self.connect(host, port)
  File "/usr/lib/python3.10/smtplib.py", line 341, in connect
    self.sock = self._get_socket(host, port, self.timeout)
  File "/usr/lib/python3.10/smtplib.py", line 312, in _get_socket
    return socket.create_connection((host, port), timeout,
  File "/usr/lib/python3.10/socket.py", line 845, in create_connection
    raise err
  File "/usr/lib/python3.10/socket.py", line 833, in create_connection
    sock.connect(sa)
ConnectionRefusedError: [Errno 111] Connection refused
[2022-11-18T06:29:41.857+0000] {standard_task_runner.py:100} ERROR - Failed to execute job 16 for task Create_Tables (The conn_id `redshift_tci` isn't defined; 7661)
[2022-11-18T06:29:41.895+0000] {local_task_job.py:164} INFO - Task exited with return code 1
[2022-11-18T06:29:41.918+0000] {local_task_job.py:273} INFO - 0 downstream tasks scheduled from follow-on schedule check
