[2022-11-18T06:19:36.207+0000] {taskinstance.py:1165} INFO - Dependencies all met for <TaskInstance: jobs_analysis.Create_Tables manual__2022-11-18T06:11:10.201511+00:00 [queued]>
[2022-11-18T06:19:36.212+0000] {taskinstance.py:1165} INFO - Dependencies all met for <TaskInstance: jobs_analysis.Create_Tables manual__2022-11-18T06:11:10.201511+00:00 [queued]>
[2022-11-18T06:19:36.212+0000] {taskinstance.py:1362} INFO - 
--------------------------------------------------------------------------------
[2022-11-18T06:19:36.212+0000] {taskinstance.py:1363} INFO - Starting attempt 2 of 4
[2022-11-18T06:19:36.212+0000] {taskinstance.py:1364} INFO - 
--------------------------------------------------------------------------------
[2022-11-18T06:19:36.222+0000] {taskinstance.py:1383} INFO - Executing <Task(PostgresOperator): Create_Tables> on 2022-11-18 06:11:10.201511+00:00
[2022-11-18T06:19:36.225+0000] {standard_task_runner.py:55} INFO - Started process 7007 to run task
[2022-11-18T06:19:36.228+0000] {standard_task_runner.py:82} INFO - Running: ['airflow', 'tasks', 'run', 'jobs_analysis', 'Create_Tables', 'manual__2022-11-18T06:11:10.201511+00:00', '--job-id', '9', '--raw', '--subdir', 'DAGS_FOLDER/jobs_dag.py', '--cfg-path', '/tmp/tmp214i9_nc']
[2022-11-18T06:19:36.229+0000] {standard_task_runner.py:83} INFO - Job 9: Subtask Create_Tables
[2022-11-18T06:19:36.262+0000] {task_command.py:376} INFO - Running <TaskInstance: jobs_analysis.Create_Tables manual__2022-11-18T06:11:10.201511+00:00 [running]> on host ip-172-31-2-28.us-west-1.compute.internal
[2022-11-18T06:19:36.293+0000] {taskinstance.py:1590} INFO - Exporting the following env vars:
AIRFLOW_CTX_DAG_EMAIL=lohitha.vanteru@sjsu.edu
AIRFLOW_CTX_DAG_OWNER=Theinsightco
AIRFLOW_CTX_DAG_ID=jobs_analysis
AIRFLOW_CTX_TASK_ID=Create_Tables
AIRFLOW_CTX_EXECUTION_DATE=2022-11-18T06:11:10.201511+00:00
AIRFLOW_CTX_TRY_NUMBER=2
AIRFLOW_CTX_DAG_RUN_ID=manual__2022-11-18T06:11:10.201511+00:00
[2022-11-18T06:19:36.298+0000] {taskinstance.py:1851} ERROR - Task failed with exception
Traceback (most recent call last):
  File "/home/ubuntu/.venv/lib/python3.10/site-packages/airflow/providers/postgres/operators/postgres.py", line 94, in execute
    self.hook.run(self.sql, self.autocommit, parameters=self.parameters)
  File "/home/ubuntu/.venv/lib/python3.10/site-packages/airflow/providers/common/sql/hooks/sql.py", line 288, in run
    with closing(self.get_conn()) as conn:
  File "/home/ubuntu/.venv/lib/python3.10/site-packages/airflow/providers/postgres/hooks/postgres.py", line 88, in get_conn
    conn = deepcopy(self.connection or self.get_connection(conn_id))
  File "/home/ubuntu/.venv/lib/python3.10/site-packages/airflow/hooks/base.py", line 70, in get_connection
    conn = Connection.get_connection_from_secrets(conn_id)
  File "/home/ubuntu/.venv/lib/python3.10/site-packages/airflow/models/connection.py", line 432, in get_connection_from_secrets
    raise AirflowNotFoundException(f"The conn_id `{conn_id}` isn't defined")
airflow.exceptions.AirflowNotFoundException: The conn_id `redshift_tci` isn't defined
[2022-11-18T06:19:36.301+0000] {taskinstance.py:1401} INFO - Marking task as UP_FOR_RETRY. dag_id=jobs_analysis, task_id=Create_Tables, execution_date=20221118T061110, start_date=20221118T061936, end_date=20221118T061936
[2022-11-18T06:19:36.309+0000] {standard_task_runner.py:100} ERROR - Failed to execute job 9 for task Create_Tables (The conn_id `redshift_tci` isn't defined; 7007)
[2022-11-18T06:19:36.319+0000] {local_task_job.py:164} INFO - Task exited with return code 1
[2022-11-18T06:19:36.334+0000] {local_task_job.py:273} INFO - 0 downstream tasks scheduled from follow-on schedule check
